Workbook

Sheet Data
A1: Month | B1: Risk-free return | C1: VFINX return | D1: FBDIX return | E1: FKUTX return | F1: PTLAX return | G1: VMNFX return
A2: 38353 | B2: 0.0016 | C2: -0.024543174 | D2: -0.061684681 | E2: 0.0090171326 | F2: -0.0012842857 | G2: 0.0027297543
A3: 38384 | B3: 0.0016 | C3: 0.020936639 | D3: -0.069910626 | E3: 0.0080428954 | F3: -0.0017122395 | G3: 0.020871143
A4: 38412 | B4: 0.0021 | C4: -0.017600418 | D4: -0.034593209 | E4: 0.0027243286 | F4: -0.0010548926 | G4: 0.018666667
A5: 38443 | B5: 0.0021 | C5: -0.019119404 | D5: 0.01857996 | E5: 0.022301517 | F5: 0.0061254799 | G5: -0.02530541
A6: 38473 | B6: 0.0024 | C6: 0.031674632 | D6: 0.05276873 | E6: 0.018324607 | F6: 0.0032741223 | G6: 0.019695613
A7: 38504 | B7: 0.0023 | C7: 0.0012720343 | D7: 0.041666667 | E7: 0.044083882 | F7: 0.001267168 | G7: 0.012291484
A8: 38534 | B8: 0.0024 | C8: 0.03706402 | D8: 0.12534653 | E8: 0.015728477 | F8: -0.0025471195 | G8: -0.018213356
A9: 38565 | B9: 0.003 | C9: -0.0091324201 | D9: -0.0066866092 | E9: 0.0089649552 | F9: 0.0065302344 | G9: 0.0026501767
A10: 38596 | B10: 0.0029 | C10: 0.007940567 | D10: 0.0014171833 | E10: 0.025232831 | F10: -0.004349498 | G10: 0.027312775
A11: 38626 | B11: 0.0027 | C11: -0.016784452 | D11: -0.042632231 | E11: -0.057188245 | F11: -0.0021354641 | G11: 0.0094339623
A12: 38657 | B12: 0.0031 | C12: 0.037646002 | D12: 0.038987435 | E12: 0.0025273799 | F12: 0.0018730478 | G12: 0.0016992353
A13: 38687 | B13: 0.0032 | C13: 0.00021939209 | D13: 0.0072914814 | E13: 0.0059268594 | F13: 0.0047851565 | G13: 0.022013251
... A241: 45627 | B241: 0.0037 | C241: -0.023956264 | D241: -0.064955425 | E241: -0.069216276 | F241: 0.0032543351 | G241: 0.0019653651

Sheet Excess returns
A1: Month | B1: VFINX return | C1: FBDIX return | D1: FKUTX return | E1: PTLAX return | F1: VMNFX return | H1: 50/50 FKUTX VMNFX
A2: 38353 | B2: =Data!C2-Data!$B2 -> -0.026143174 | C2: =Data!D2-Data!$B2 -> -0.063284681 | D2: =Data!E2-Data!$B2 -> 0.0074171326 | E2: =Data!F2-Data!$B2 -> -0.0028842857 | F2: =Data!G2-Data!$B2 -> 0.0011297543 | H2: =0.5*D2 + 0.5*F2 -> 0.0042734434
A3: 38384 | B3: =Data!C3-Data!$B3 -> 0.019336639 | C3: =Data!D3-Data!$B3 -> -0.071510626 | D3: =Data!E3-Data!$B3 -> 0.0064428954 | E3: =Data!F3-Data!$B3 -> -0.0033122395 | F3: =Data!G3-Data!$B3 -> 0.019271143 | H3: =0.5*D3 + 0.5*F3 -> 0.012857019
A4: 38412 | B4: =Data!C4-Data!$B4 -> -0.019700418 | C4: =Data!D4-Data!$B4 -> -0.036693209 | D4: =Data!E4-Data!$B4 -> 0.00062432864 | E4: =Data!F4-Data!$B4 -> -0.0031548926 | F4: =Data!G4-Data!$B4 -> 0.016566667 | H4: =0.5*D4 + 0.5*F4 -> 0.0085954977
A5: 38443 | B5: =Data!C5-Data!$B5 -> -0.021219404 | C5: =Data!D5-Data!$B5 -> 0.01647996 | D5: =Data!E5-Data!$B5 -> 0.020201517 | E5: =Data!F5-Data!$B5 -> 0.0040254799 | F5: =Data!G5-Data!$B5 -> -0.02740541 | H5: =0.5*D5 + 0.5*F5 -> -0.0036019468
A6: 38473 | B6: =Data!C6-Data!$B6 -> 0.029274632 | C6: =Data!D6-Data!$B6 -> 0.05036873 | D6: =Data!E6-Data!$B6 -> 0.015924607 | E6: =Data!F6-Data!$B6 -> 0.0008741223 | F6: =Data!G6-Data!$B6 -> 0.017295613 | H6: =0.5*D6 + 0.5*F6 -> 0.01661011
A7: 38504 | B7: =Data!C7-Data!$B7 -> -0.0010279657 | C7: =Data!D7-Data!$B7 -> 0.039366667 | D7: =Data!E7-Data!$B7 -> 0.041783882 | E7: =Data!F7-Data!$B7 -> -0.001032832 | F7: =Data!G7-Data!$B7 -> 0.0099914838 | H7: =0.5*D7 + 0.5*F7 -> 0.025887683
A8: 38534 | B8: =Data!C8-Data!$B8 -> 0.03466402 | C8: =Data!D8-Data!$B8 -> 0.12294653 | D8: =Data!E8-Data!$B8 -> 0.013328477 | E8: =Data!F8-Data!$B8 -> -0.0049471195 | F8: =Data!G8-Data!$B8 -> -0.020613356 | H8: =0.5*D8 + 0.5*F8 -> -0.0036424398
A9: 38565 | B9: =Data!C9-Data!$B9 -> -0.01213242 | C9: =Data!D9-Data!$B9 -> -0.0096866092 | D9: =Data!E9-Data!$B9 -> 0.0059649552 | E9: =Data!F9-Data!$B9 -> 0.0035302344 | F9: =Data!G9-Data!$B9 -> -0.00034982332 | H9: =0.5*D9 + 0.5*F9 -> 0.0028075659
A10: 38596 | B10: =Data!C10-Data!$B10 -> 0.005040567 | C10: =Data!D10-Data!$B10 -> -0.0014828167 | D10: =Data!E10-Data!$B10 -> 0.022332831 | E10: =Data!F10-Data!$B10 -> -0.007249498 | F10: =Data!G10-Data!$B10 -> 0.024412775 | H10: =0.5*D10 + 0.5*F10 -> 0.023372803
A11: 38626 | B11: =Data!C11-Data!$B11 -> -0.019484452 | C11: =Data!D11-Data!$B11 -> -0.045332231 | D11: =Data!E11-Data!$B11 -> -0.059888245 | E11: =Data!F11-Data!$B11 -> -0.0048354641 | F11: =Data!G11-Data!$B11 -> 0.0067339623 | H11: =0.5*D11 + 0.5*F11 -> -0.026577141
A12: 38657 | B12: =Data!C12-Data!$B12 -> 0.034546002 | C12: =Data!D12-Data!$B12 -> 0.035887435 | D12: =Data!E12-Data!$B12 -> -0.00057262005 | E12: =Data!F12-Data!$B12 -> -0.0012269522 | F12: =Data!G12-Data!$B12 -> -0.0014007647 | H12: =0.5*D12 + 0.5*F12 -> -0.00098669235
A13: 38687 | B13: =Data!C13-Data!$B13 -> -0.0029806079 | C13: =Data!D13-Data!$B13 -> 0.0040914814 | D13: =Data!E13-Data!$B13 -> 0.0027268594 | E13: =Data!F13-Data!$B13 -> 0.0015851565 | F13: =Data!G13-Data!$B13 -> 0.018813251 | H13: =0.5*D13 + 0.5*F13 -> 0.010770055
... A241: 45627 | B241: =Data!C241-Data!$B241 -> -0.027656264 | C241: =Data!D241-Data!$B241 -> -0.068655425 | D241: =Data!E241-Data!$B241 -> -0.072916276 | E241: =Data!F241-Data!$B241 -> -0.00044566486 | F241: =Data!G241-Data!$B241 -> -0.0017346349 | H241: =0.5*D241 + 0.5*F241 -> -0.037325456

Sheet Analysis
A1: Fund: | B1: VFINX | C1: FBDIX | D1: FKUTX | E1: PTLAX | F1: VMNFX
A3: 1. Which funds, if any, had Sharpe ratios higher than VFINX in the data?
A5: Average excess return | B5: =AVERAGE('Excess returns'!B2:B241) -> 0.0078001687 | C5: =AVERAGE('Excess returns'!C2:C241) -> 0.0076908286 | D5: =AVERAGE('Excess returns'!D2:D241) -> 0.0067438047 | E5: =AVERAGE('Excess returns'!E2:E241) -> 0.00070233744 | F5: =AVERAGE('Excess returns'!F2:F241) -> 0.0012312315
A6: Volatility of excess return | B6: =STDEV('Excess returns'!B2:B241) -> 0.043340114 | C6: =STDEV('Excess returns'!C2:C241) -> 0.0609928 | D6: =STDEV('Excess returns'!D2:D241) -> 0.039441439 | E6: =STDEV('Excess returns'!E2:E241) -> 0.0074463024 | F6: =STDEV('Excess returns'!F2:F241) -> 0.016962668
A7: Sharpe ratio | B7: =B5/B6 -> 0.17997573 | C7: =C5/C6 -> 0.12609404 | D7: =D5/D6 -> 0.17098272 | E7: =E5/E6 -> 0.094320296 | F7: =F5/F6 -> 0.072584779
A9: Answer: | B9: None of the funds had a higher Sharpe ratio than VFINX in this data.
A12: 2. Calculate the beta and alpha of each fund with respect to VFINX, using the formulas in the slides.
A14: Correlation w/ VFINX | C14: =CORREL('Excess returns'!C2:C241,'Excess returns'!$B2:$B241) -> 0.5918067 | D14: =CORREL('Excess returns'!D2:D241,'Excess returns'!$B2:$B241) -> 0.56496738 | E14: =CORREL('Excess returns'!E2:E241,'Excess returns'!$B2:$B241) -> 0.39675373 | F14: =CORREL('Excess returns'!F2:F241,'Excess returns'!$B2:$B241) -> -0.0067434238
A15: Beta w.r.t. VFINX | C15: =C14*C6/$B6 -> 0.83285308 | D15: =D14*D6/$B6 -> 0.51414555 | E15: =E14*E6/$B6 -> 0.068166602 | F15: =F14*F6/$B6 -> -0.0026392745
A16: Alpha w.r.t. VFINX | C16: =C5-C15*$B5 -> 0.001194434 | D16: =D5-D15*$B5 -> 0.0027333826 | E16: =E5-E15*$B5 -> 0.00017062645 | F16: =F5-F15*$B5 -> 0.0012518183
A18: 3. Calculate the same numbers by running a regression. I will use Excel’s SLOPE and INTERCEPT functions.
A20: Beta w.r.t. VFINX | C20: =SLOPE('Excess returns'!C2:C241,'Excess returns'!$B2:$B241) -> 0.83285308 | D20: =SLOPE('Excess returns'!D2:D241,'Excess returns'!$B2:$B241) -> 0.51414555 | E20: =SLOPE('Excess returns'!E2:E241,'Excess returns'!$B2:$B241) -> 0.068166602 | F20: =SLOPE('Excess returns'!F2:F241,'Excess returns'!$B2:$B241) -> -0.0026392745
A21: Alpha w.r.t. VFINX | C21: =INTERCEPT('Excess returns'!C2:C241,'Excess returns'!$B2:$B241) -> 0.001194434 | D21: =INTERCEPT('Excess returns'!D2:D241,'Excess returns'!$B2:$B241) -> 0.0027333826 | E21: =INTERCEPT('Excess returns'!E2:E241,'Excess returns'!$B2:$B241) -> 0.00017062645 | F21: =INTERCEPT('Excess returns'!F2:F241,'Excess returns'!$B2:$B241) -> 0.0012518183
A23: 4. For each fund, calculate its information ratio with respect to VFINX.
A24: Then determine the highest Sharpe ratio that an investor could achieve by allocating only between VFINX and that fund.
A26: SD of regression residuals | C26: =SQRT( C6^2 - C20^2*$B6^2) -> 0.049165071 | D26: =SQRT( D6^2 - D20^2*$B6^2) -> 0.032543654 | E26: =SQRT( E6^2 - E20^2*$B6^2) -> 0.0068351478 | F26: =SQRT( F6^2 - F20^2*$B6^2) -> 0.016962282
A27: Information ratio (using formula from slides) | C27: =C21/C26 -> 0.024294362 | D27: =D21/D26 -> 0.083991265 | E27: =E21/E26 -> 0.024963095 | F27: =F21/F26 -> 0.07380011
A28: Maximum Sharpe ratio (also on slides) | C28: =SQRT($B7^2+C27^2) -> 0.18160804 | D28: =SQRT($B7^2+D27^2) -> 0.19860966 | E28: =SQRT($B7^2+E27^2) -> 0.18169871 | F28: =SQRT($B7^2+F27^2) -> 0.1945192
A30: 5. Suppose a fund manager follows a strategy of allocating half of invested funds to VMNFX, and half to FKUTX.
A31: What is the information ratio of this strategy (with respect to VFINX)?
A32: If an investor divides her money between this fund and VFINX, what is the highest Sharpe ratio that she can achieve?
A33: What weighting of VFINX and the manager's strategy will achieve this Sharpe ratio?
D34: Using formulas without explicitly simulating the strategy:
A35: Average excess return of 50/50 strategy: | B35: =AVERAGE('Excess returns'!H2:H241) -> 0.0039875181 | D35: =0.5*F5+0.5*D5 -> 0.0039875181
A36: Volatility of excess return of 50/50 strategy: | B36: =STDEV('Excess returns'!H2:H241) -> 0.021681503 | D36: =SQRT( 0.5^2*F6^2 + 0.5^2*D6^2 + 2*0.5*0.5*F6*D6*CORREL('Excess returns'!F2:F241,'Excess returns'!D2:D241)) -> 0.021681503
A37: Correlation of excess return w/VFINX: | B37: =CORREL('Excess returns'!H2:H241,'Excess returns'!B2:B241) -> 0.51123623
A39: Beta of the 50/50 strategy using formula: | B39: =B37*B36/B6 -> 0.25575314 | D39: =0.5*F15+0.5*D15 -> 0.25575314
A40: Beta of the 50/50 strategy using SLOPE: | B40: =SLOPE('Excess returns'!H2:H241,'Excess returns'!B2:B241) -> 0.25575314
A41: Alpha of the 50/50 strategy using formula: | B41: =B35-B39*B5 -> 0.0019926005 | D41: =D35 - D39*B5 -> 0.0019926005
A42: Alpha of the 50/50 strategy using INTERCEPT: | B42: =INTERCEPT('Excess returns'!H2:H241,'Excess returns'!B2:B241) -> 0.0019926005
A43: SD of regression residuals using formula: | B43: =SQRT(B36^2-B39^2*B6^2) -> 0.018633956 | D43: =SQRT( D36^2 - D39^2*B6^2) -> 0.018633956
A45: Information ratio of 50/50 strategy | B45: =B42/B43 -> 0.10693384 | D45: =D41/D43 -> 0.10693384
A46: Max attainable Sharpe ratio | B46: =SQRT(B7^2+B45^2) -> 0.20934687 | D46: =SQRT(D45^2+B7^2) -> 0.20934687
A48: Portfolio weights to achieve the above Sharpe ratio (using matrix formulas, but you can also do it by trial and error):
A50: Covariance matrix:
B51: VFINX | C51: 50/50
A52: VFINX | B52: =B6^2 -> 0.0018783654 | C52: =B37*B36*B6 -> 0.00048039785
A53: 50/50 | B53: =B37*B36*B6 -> 0.00048039785 | C53: =B36^2 -> 0.00047008758
A54: Average excess returns:
A55: VFINX | B55: =B5 -> 0.0078001687
...
